Traceback (most recent call last):
  File "/Users/vero/opt/anaconda3/envs/jbook/lib/python3.10/site-packages/jupyter_cache/executors/utils.py", line 51, in single_nb_execution
    executenb(
  File "/Users/vero/opt/anaconda3/envs/jbook/lib/python3.10/site-packages/nbclient/client.py", line 1085, in execute
    return NotebookClient(nb=nb, resources=resources, km=km, **kwargs).execute()
  File "/Users/vero/opt/anaconda3/envs/jbook/lib/python3.10/site-packages/nbclient/util.py", line 84, in wrapped
    return just_run(coro(*args, **kwargs))
  File "/Users/vero/opt/anaconda3/envs/jbook/lib/python3.10/site-packages/nbclient/util.py", line 62, in just_run
    return loop.run_until_complete(coro)
  File "/Users/vero/opt/anaconda3/envs/jbook/lib/python3.10/asyncio/base_events.py", line 641, in run_until_complete
    return future.result()
  File "/Users/vero/opt/anaconda3/envs/jbook/lib/python3.10/site-packages/nbclient/client.py", line 551, in async_execute
    await self.async_execute_cell(
  File "/Users/vero/opt/anaconda3/envs/jbook/lib/python3.10/site-packages/nbclient/client.py", line 846, in async_execute_cell
    self._check_raise_for_error(cell, exec_reply)
  File "/Users/vero/opt/anaconda3/envs/jbook/lib/python3.10/site-packages/nbclient/client.py", line 748, in _check_raise_for_error
    raise CellExecutionError.from_cell_and_msg(cell, exec_reply_content)
nbclient.exceptions.CellExecutionError: An error occurred while executing the following cell:
------------------
word_count_sorted('tomsawyer.txt', 'tomsawyer.counts')
------------------

[0;31m---------------------------------------------------------------------------[0m
[0;31mFileNotFoundError[0m                         Traceback (most recent call last)
[0;32m/var/folders/82/jclchxtc8v5c1z006s6fwjm9v2lh42/T/ipykernel_31160/2275969890.py[0m in [0;36m<module>[0;34m[0m
[0;32m----> 1[0;31m [0mword_count_sorted[0m[0;34m([0m[0;34m'tomsawyer.txt'[0m[0;34m,[0m [0;34m'tomsawyer.counts'[0m[0;34m)[0m[0;34m[0m[0;34m[0m[0m
[0m
[0;32m/var/folders/82/jclchxtc8v5c1z006s6fwjm9v2lh42/T/ipykernel_31160/1418562632.py[0m in [0;36mword_count_sorted[0;34m(input_file, output_file)[0m
[1;32m      6[0m [0;32mdef[0m [0mword_count_sorted[0m[0;34m([0m[0minput_file[0m[0;34m,[0m [0moutput_file[0m[0;34m)[0m[0;34m:[0m[0;34m[0m[0;34m[0m[0m
[1;32m      7[0m [0;34m[0m[0m
[0;32m----> 8[0;31m     [0mf[0m [0;34m=[0m [0mopen[0m[0;34m([0m[0minput_file[0m[0;34m,[0m [0;34m'r'[0m[0;34m)[0m[0;34m[0m[0;34m[0m[0m
[0m[1;32m      9[0m     [0mtxt[0m  [0;34m=[0m [0mf[0m[0;34m.[0m[0mread[0m[0;34m([0m[0;34m)[0m[0;34m[0m[0;34m[0m[0m
[1;32m     10[0m     [0mf[0m[0;34m.[0m[0mclose[0m[0;34m([0m[0;34m)[0m[0;34m[0m[0;34m[0m[0m

[0;31mFileNotFoundError[0m: [Errno 2] No such file or directory: 'tomsawyer.txt'
FileNotFoundError: [Errno 2] No such file or directory: 'tomsawyer.txt'

